<?xml version="1.0"?>

<robot name="rdc_biped_robot">


<!-- Base -->

  <link name="base_link"/>
  <joint name="CPG" type="fixed">
    <parent link="base_link"/>
    <child link="body"/>
    <origin rpy="0 0 0" xyz="0 0 0.333"/>
  </joint>


<!-- Body -->

  <link name="body">
    <visual>
      <origin rpy="0 0 0" xyz="-0.091 0 0"/>
      <geometry>
        <mesh filename="packages://robot_descirption/models/rdc_robot_v1/meshes/body.stl" scale="1 1 1"/>
      </geometry>
    </visual>
    <collision>
       <origin rpy="0 0 0" xyz="-0.091 0 0"/>
      <geometry>      
        <mesh filename="packages://robot_descirption/models/rdc_robot_v1/meshes/body.stl" scale="1 1 1"/>
      </geometry>
    </collision>
    <inertial>
      <origin xyz="0 0 0"/>
      <mass value="1.128279"/>
      <inertia ixx="0.007256487589" ixy="0.0" ixz="0.0" iyy="0.014750857631" iyz="0.0" izz="0.010668084267"/>
    </inertial>
  </link>

  <joint name="luggage" type="fixed">
    <parent link="body"/>
    <child link="body_luggage"/>
    <origin rpy="0 0 0" xyz="-0.091 0 0"/>
  </joint>

  <link name="body_luggage">
    <visual>
      <origin rpy="0 0 0" xyz="0.085 0 0.185"/>
      <geometry>
        <mesh filename="packages://robot_descirption/models/rdc_robot_v1/meshes/body_luggage.stl" scale="1 1 1"/>
      </geometry>
    </visual>
    <collision>
      <origin rpy="0 0 0" xyz="0.085 0 0.185"/>
      <geometry>
        <mesh filename="packages://robot_descirption/models/rdc_robot_v1/meshes/body_luggage.stl" scale="1 1 1"/>
      </geometry>
    </collision>
    <inertial>
      <origin xyz="0 0 0"/>
      <mass value="6.002284"/>
      <inertia ixx="0.021219922175" ixy="0.0" ixz="0.0" iyy="0.059412361786" iyz="0.0" izz="0.056129347719"/>
    </inertial>
  </link>


<!-- Right Leg -->

  <joint name="r_waist_roll" type="revolute">
    <parent link="body"/>
    <child link="r_wr2wp"/>
    <origin rpy="0 0 0" xyz="-0.091 -0.075 0"/>
    <axis xyz="1 0 0"/>
    <limit effort="7.2" lower="-6.28" upper="6.28" velocity="11.519173063"/>
  </joint>

  <link name="r_wr2wp">
    <visual>
      <origin rpy="0 0 0" xyz="0.091 0.00 0.00"/>
      <geometry>
        <mesh filename="packages://robot_descirption/models/rdc_robot_v1/meshes/link_wr2wp_r.stl" scale="1 1 1"/>
      </geometry>
    </visual>
    <collision>
      <origin rpy="0 0 0" xyz="0.091 0.00 0.00"/>
      <geometry>
        <mesh filename="packages://robot_descirption/models/rdc_robot_v1/meshes/link_wr2wp_r.stl" scale="1 1 1"/>
      </geometry>
   </collision>
    <inertial>
      <origin xyz="0 0 0"/>
      <mass value="1.463019"/>
      <inertia ixx="0.001749718494" ixy="0.0" ixz="0.0" iyy="0.003223385949" iyz="0.0" izz="0.003263127737"/>
    </inertial>
 </link>

  <joint name="r_waist_pitch" type="revolute">
    <parent link="r_wr2wp"/>
    <child link="r_wp2kp"/>
    <origin rpy="0 0 0" xyz="0.091 -0.055 0.00"/>
    <axis xyz="0 1 0"/>
     <limit effort="7.2" lower="-6.28" upper="6.28" velocity="11.519173063"/>
  </joint>

  <link name="r_wp2kp">
    <visual>
      <origin rpy="0 0 0" xyz="0 0 -0.08"/>
      <geometry>
        <mesh filename="packages://robot_descirption/models/rdc_robot_v1/meshes/link_wp2kp.stl" scale="1 1 1"/>
      </geometry>
    </visual>
    <collision>
      <origin rpy="0 0 0" xyz="0 0 -0.08"/>
      <geometry>
        <mesh filename="packages://robot_descirption/models/rdc_robot_v1/meshes/link_wp2kp.stl" scale="1 1 1"/>
      </geometry>
    </collision>
    <inertial>
      <origin xyz="0 0 0"/>
      <mass value="0.581098"/>
      <inertia ixx="0.00300565539" ixy="0.0" ixz="0.0" iyy="0.00339409955" iyz="0.0" izz="0.000580175165"/>
    </inertial>
 </link>

  <joint name="r_knee_pitch" type="revolute">
    <parent link="r_wp2kp"/>
    <child link="r_kp2heel"/>
    <origin rpy="0 0 0" xyz="0 0 -0.16"/>
    <axis xyz="0 1 0"/>
     <limit effort="7.2" lower="-6.28" upper="6.28" velocity="11.519173063"/>
  </joint>
  
  <link name="r_kp2heel">
    <visual>
      <origin rpy="0 0 0" xyz="0 0 -0.0746675"/>
      <geometry>
        <mesh filename="packages://robot_descirption/models/rdc_robot_v1/meshes/link_kp2heel.stl" scale="1 1 1"/>
      </geometry>
    </visual>
    <collision>
      <origin rpy="0 0 0" xyz="0 0 -0.0746675"/>
      <geometry>
        <mesh filename="packages://robot_descirption/models/rdc_robot_v1/meshes/link_kp2heel.stl" scale="1 1 1"/>
      </geometry>
    </collision>
    <inertial>
      <origin xyz="0 0 0"/>
      <mass value="0.199496"/>
      <inertia ixx="0.000038569077" ixy="0.0" ixz="0.0" iyy="0.000690047835" iyz="0.0" izz="0.000672474784"/>
    </inertial>
 </link>

  <joint name="r_ankle" type="fixed">
    <parent link="r_kp2heel"/>
    <child link="r_heel2end"/>
    <origin rpy="0 0 0" xyz="0 0 -0.149335"/>
  </joint>

  <link name="r_heel2end">
     <visual>
      <origin rpy="0 0 0" xyz="0 0 0"/>
      <geometry>
        <mesh filename="packages://robot_descirption/models/rdc_robot_v1/meshes/link_heel2end.stl" scale="1 1 1"/>
      </geometry>
    </visual>
    <collision>
      <origin rpy="0 0 0" xyz="0 0 0"/>
      <geometry>
        <mesh filename="packages://robot_descirption/models/rdc_robot_v1/meshes/link_heel2end.stl" scale="1 1 1"/>
      </geometry>
    </collision>
    <inertial>
      <origin xyz="0 0 0"/>
      <mass value="0.0"/>
      <inertia ixx="0.0" ixy="0.0" ixz="0.0" iyy="0.0" iyz="0.0" izz="0.0"/>
      <!--<mass value="0.1"/>-->
      <!--<inertia ixx="0.01" ixy="0.0" ixz="0.0" iyy="0.01" iyz="0.0" izz="0.01"/>-->
    </inertial>
  </link>


<!-- Left Leg -->

  <joint name="l_waist_roll" type="revolute">
    <parent link="body"/>
    <child link="l_wr2wp"/>
    <origin rpy="0 0 0" xyz="-0.091 0.075 0"/>
    <axis xyz="1 0 0"/>
    <limit effort="7.2" lower="-6.28" upper="6.28" velocity="11.519173063"/>
  </joint>

  <link name="l_wr2wp">
    <visual>
      <origin rpy="0 0 0" xyz="0.091 0.00 0.00"/>
      <geometry>
        <mesh filename="packages://robot_descirption/models/rdc_robot_v1/meshes/link_wr2wp_l.stl" scale="1 1 1"/>
      </geometry>
    </visual>
    <collision>
      <origin rpy="0 0 0" xyz="0.091 0.00 0.00"/>
      <geometry>
        <mesh filename="packages://robot_descirption/models/rdc_robot_v1/meshes/link_wr2wp_l.stl" scale="1 1 1"/>
      </geometry>
   </collision>
    <inertial>
      <origin xyz="0 0 0"/>
      <mass value="1.463019"/>
      <inertia ixx="0.001749718494" ixy="0.0" ixz="0.0" iyy="0.003223385949" iyz="0.0" izz="0.003263127737"/>
    </inertial>
 </link>

  <joint name="l_waist_pitch" type="revolute">
    <parent link="l_wr2wp"/>
    <child link="l_wp2kp"/>
    <origin rpy="0 0 0" xyz="0.091 0.055 0.00"/>
    <axis xyz="0 1 0"/>
     <limit effort="7.2" lower="-6.28" upper="6.28" velocity="11.519173063"/>
  </joint>

  <link name="l_wp2kp">
    <visual>
      <origin rpy="0 0 0" xyz="0 0 -0.08"/>
      <geometry>
        <mesh filename="packages://robot_descirption/models/rdc_robot_v1/meshes/link_wp2kp.stl" scale="1 1 1"/>
      </geometry>
    </visual>
    <collision>
      <origin rpy="0 0 0" xyz="0 0 -0.08"/>
      <geometry>
        <mesh filename="packages://robot_descirption/models/rdc_robot_v1/meshes/link_wp2kp.stl" scale="1 1 1"/>
      </geometry>
    </collision>
    <inertial>
      <origin xyz="0 0 0"/>
      <mass value="0.581098"/>
      <inertia ixx="0.00300565539" ixy="0.0" ixz="0.0" iyy="0.00339409955" iyz="0.0" izz="0.000580175165"/>
    </inertial>
 </link>

  <joint name="l_knee_pitch" type="revolute">
    <parent link="l_wp2kp"/>
    <child link="l_kp2heel"/>
    <origin rpy="0 0 0" xyz="0 0 -0.16"/>
    <axis xyz="0 1 0"/>
     <limit effort="7.2" lower="-6.28" upper="6.28" velocity="11.519173063"/>
  </joint>
  
  <link name="l_kp2heel">
    <visual>
      <origin rpy="0 0 0" xyz="0 0 -0.0746675"/>
      <geometry>
        <mesh filename="packages://robot_descirption/models/rdc_robot_v1/meshes/link_kp2heel.stl" scale="1 1 1"/>
      </geometry>
    </visual>
    <collision>
      <origin rpy="0 0 0" xyz="0 0 -0.0746675"/>
      <geometry>
        <mesh filename="packages://robot_descirption/models/rdc_robot_v1/meshes/link_kp2heel.stl" scale="1 1 1"/>
      </geometry>
    </collision>
    <inertial>
      <origin xyz="0 0 0"/>
      <mass value="0.199496"/>
      <inertia ixx="0.000038569077" ixy="0.0" ixz="0.0" iyy="0.000690047835" iyz="0.0" izz="0.000672474784"/>
    </inertial>
 </link>

  <joint name="l_ankle" type="fixed">
    <parent link="l_kp2heel"/>
    <child link="l_heel2end"/>
    <origin rpy="0 0 0" xyz="0 0 -0.149335"/>
  </joint>
  
  <link name="l_heel2end">
     <visual>
      <origin rpy="0 0 0" xyz="0 0 0"/>
      <geometry>
        <mesh filename="packages://robot_descirption/models/rdc_robot_v1/meshes/link_heel2end.stl" scale="1 1 1"/>
      </geometry>
    </visual>
    <collision>
      <origin rpy="0 0 0" xyz="0 0 0"/>
      <geometry>
        <mesh filename="packages://robot_descirption/models/rdc_robot_v1/meshes/link_heel2end.stl" scale="1 1 1"/>
      </geometry>
    </collision>
    <inertial>
      <origin xyz="0 0 0"/>
      <mass value="0.0"/>
      <inertia ixx="0.0" ixy="0.0" ixz="0.0" iyy="0.0" iyz="0.0" izz="0.0"/>
      <!--<mass value="0.1"/>-->
      <!--<inertia ixx="0.01" ixy="0.0" ixz="0.0" iyy="0.01" iyz="0.0" izz="0.01"/>-->
    </inertial>
  </link>

</robot>